<?xml version="1.0" encoding="UTF-8"?>
<robot xmlns:xacro="http://wiki.ros.org/wiki/xacro">

   <xacro:include filename="inertial_macros.xacro"/>
   
   <material name="white">
      <color rgba="1 1 1 1"/>
   </material>

   <material name="black">
      <color rgba="0 0 0 1"/>
   </material>

   <material name="gray">
      <color rgba="0.8 0.78 0.78 1"/>
   </material>

   <!-- BASE LINK -->
   <link name="base_link"></link>

   <!-- CHASSIS -->
   <joint name="chassis_joint" type="fixed">
      <origin xyz="-0.0825 0.0 0.0"/>
      <parent link="base_link"/>
      <child link="chassis"/>
   </joint>
   
   <link name="chassis">
      <visual>
         <origin xyz="0.0825 0.0 0.29"/>
         <geometry>
            <box size="0.165 0.319 0.575"/>
         </geometry>  
         <material name="white"/> 
      </visual>
      <collision>
         <origin xyz="0.0825 0.0 0.29"/>
         <geometry>
            <box size="0.165 0.319 0.575"/>
         </geometry>  
      </collision>
      <xacro:inertial_box mass="2" x="0.165" y="0.319" z="0.575">
         <origin xyz="0.0825 0.0 0.29" rpy="0.0 0.0 0.0"/>
      </xacro:inertial_box>
   </link>

   <joint name="front_caster_holder_joint" type="fixed">
      <origin xyz="0.165 0.0 0.0"/>
      <parent link="chassis"/>
      <child link="front_caster_holder"/>
   </joint>

   <link name="front_caster_holder">
      <visual>
         <origin xyz="0.08 0.0 0.025"/>
         <geometry>
            <box size="0.160 0.085 0.050"/>
         </geometry>  
         <material name="white"/> 
      </visual>
      <collision>
         <origin xyz="0.08 0.0 0.025"/>
         <geometry>
            <box size="0.160 0.085 0.050"/>
         </geometry>   
      </collision>
      <xacro:inertial_box mass="0.08" x="0.16" y="0.085" z="0.050">
         <origin xyz="0.08 0.0 0.025" rpy="0.0 0.0 0.0"/>
      </xacro:inertial_box>
   </link>

   <joint name="back_caster_holder_joint" type="fixed">
      <origin xyz="0.0 0.0 0.0"/>
      <parent link="chassis"/>
      <child link="back_caster_holder"/>
   </joint>

   <link name="back_caster_holder">
      <visual>
         <origin xyz="-0.035 0.0 0.01"/>
         <geometry>
            <box size="0.07 0.1 0.02"/>
         </geometry>  
         <material name="white"/> 
      </visual>
      <collision>
         <origin xyz="-0.035 0.0 0.01"/>
         <geometry>
            <box size="0.07 0.1 0.02"/>
         </geometry>  
      </collision>
      <xacro:inertial_box mass="0.05" x="0.07" y="0.1" z="0.02">
         <origin xyz="-0.035 0.0 0.01" rpy="0.0 0.0 0.0"/>
      </xacro:inertial_box>
   </link>

   <!-- WHEELS -->

   <joint name="left_wheel_joint" type="continuous">
      <parent link="base_link"/>
      <child link="left_wheel"/>
      <origin xyz="0 0.177 -0.025" rpy="-${pi/2} 0 0"/>
      <axis xyz="0.0 0.0 1"/>
   </joint>

   <link name="left_wheel">
      <visual>
         <geometry>
            <cylinder radius="0.041" length="0.035"/>
         </geometry>
         <material name="black"/>
      </visual>
      <collision>
         <geometry>
            <cylinder radius="0.041" length="0.035"/>
         </geometry>
      </collision>
      <xacro:inertial_cylinder mass="0.15" length="0.035" radius="0.041">
         <origin xyz="0.0 0.0 0.0" rpy="0.0 0.0 0.0"/>
      </xacro:inertial_cylinder>
   </link>

   <joint name="right_wheel_joint" type="continuous">
      <parent link="base_link"/>
      <child link="right_wheel"/>
      <origin xyz="0 -0.177 -0.025" rpy="${pi/2} 0 0"/>
      <axis xyz="0.0 0.0 -1"/>
   </joint>

   <link name="right_wheel">
      <visual>
         <geometry>
            <cylinder radius="0.041" length="0.035"/>
         </geometry>
         <material name="black"/>
      </visual>
      <collision>
         <geometry>
            <cylinder radius="0.041" length="0.035"/>
         </geometry>
      </collision>
       <xacro:inertial_cylinder mass="0.15" length="0.035" radius="0.041">
         <origin xyz="0.0 0.0 0.0" rpy="0.0 0.0 0.0"/>
      </xacro:inertial_cylinder>
   </link>

   <!-- CASTER WHEELS -->
   <joint name="front_caster_wheel_joint" type="fixed">
      <parent link="front_caster_holder"/>
      <child link="front_caster_wheel"/>
      <origin xyz="0.120 0.0 -0.025"/>
   </joint>

   <link name="front_caster_wheel">
      <visual>
         <origin xyz="0.0 0.0 0.0"/>
         <geometry>
            <sphere radius="0.041"/>
         </geometry>
         <material name="black"/>
      </visual>
      <collision>
         <origin xyz="0.0 0.0 0.0"/>
         <geometry>
            <sphere radius="0.041"/>
         </geometry>
      </collision>
      <xacro:inertial_sphere mass="0.15" radius="0.041">
         <origin xyz="0.0 0.0 0.0" rpy="0.0 0.0 0.0"/>
      </xacro:inertial_sphere>
   </link>

   <joint name="back_caster_wheel_joint" type="fixed">
      <parent link="back_caster_holder"/>
      <child link="back_caster_wheel"/>
      <origin xyz="-0.035 0.0 -0.025"/>
   </joint>

   <link name="back_caster_wheel">
      <visual>
         <origin xyz="0.0 0.0 0.0"/>
         <geometry>
            <sphere radius="0.041"/>
         </geometry>
         <material name="black"/>
      </visual>
      <collision>
         <origin xyz="0.0 0.0 0.0"/>
         <geometry>
            <sphere radius="0.041"/>
         </geometry>
      </collision>
      <xacro:inertial_sphere mass="0.1" radius="0.041">
         <origin xyz="0.0 0.0 0.0" rpy="0.0 0.0 0.0"/>
      </xacro:inertial_sphere>
   </link>

</robot>